Workbook

Sheet How to use
A1: HOW TO USE THIS WORKBOOK
A3: Topic | B3: What to do
A4: Phone vs spreadsheet | B4: This IS a spreadsheet — that is what you want for lasting data. For phone: upload this file to Google Drive and open it in the Google Sheets app. Use the Log tab to add spends. No separate website needed.
A5: Daily (30 sec) | B5: Open Log → fill a yellow row at the top: Date, Description, Amount, Category, Account. Type defaults to Expense. Person defaults to Roberto.
A6: What’s left | B6: Open Dashboard → set Year + Month. “PLANNED LEFT” = Income Plan total minus expenses logged this month. Category rows show OK / CLOSE / OVER vs Budget.
A7: Paychecks | B7: Log them as Type=Income, Category=Income. Keep normal amounts on Income Plan.
A8: Rent & subs | B8: Recurring is your checklist. When charged, log once on Log so Dashboard counts it.
A9: Accounts | B9: Update balances on Accounts when you check the bank/app. Cards: put amount owed in Owed.
A10: Never again | B10: Do not make a new sheet per month. Do not copy budget blocks. Filter Log or flip Dashboard month instead.
A11: Imported history | B11: Misc + Grocery from your old file are in Log (including the weird April/May layouts). Spot-check a few rows and fix Category if needed.
A12: First setup | B12: 1) Update account balances 2) Tweak Budget numbers 3) Confirm paycheck amounts 4) Log today.

Sheet Log
A1: PERSONAL MONEY LOG
A2: Yellow rows at top = quick entry. Amounts are positive. Type = Expense / Income / Transfer. Dropdowns on Category, Account, Person.
A4: Date | B4: Description | C4: Amount | D4: Type | E4: Category | F4: Account | G4: Person | H4: Notes
D5: Expense | F5: Checking | G5: Roberto
D6: Expense | F6: Checking | G6: Roberto
D7: Expense | F7: Checking | G7: Roberto
D8: Expense | F8: Checking | G8: Roberto
D9: Expense | F9: Checking | G9: Roberto
D10: Expense | F10: Checking | G10: Roberto
D11: Expense | F11: Checking | G11: Roberto
D12: Expense | F12: Checking | G12: Roberto
D13: Expense | F13: Checking | G13: Roberto
D14: Expense | F14: Checking | G14: Roberto
D15: Expense | F15: Checking | G15: Roberto
D16: Expense | F16: Checking | G16: Roberto
... D24: Expense | F24: Checking | G24: Roberto
A25: 46163 | B25: Cat food | C25: 43.4 | D25: Expense | E25: Grocery | F25: Bilt
A26: 46163 | B26: Amazon: Protein Bars | C26: 14.99 | D26: Expense | E26: Shopping | F26: Bilt
A27: 46163 | B27: Grocery: City Fresh | C27: 39.19 | D27: Expense | E27: Grocery | F27: Bilt
A28: 46163 | B28: Amazon: Toothpast, Chlorophyll, Oil sprayer | C28: 51.01 | D28: Expense | E28: Shopping | F28: Bilt
A29: 46163 | B29: Grocery: Green Valley | C29: 21.46 | D29: Expense | E29: Grocery | F29: Bilt
A30: 46163 | B30: Rose Glycerin Spray | C30: 11.94 | D30: Expense | E30: Shopping | F30: Bilt
A31: 46163 | B31: Grocery: DoorDash | C31: 86 | D31: Expense | E31: Grocery | F31: Bilt
A32: 46163 | B32: Klarna | C32: 134.75 | D32: Expense | E32: Shopping | F32: Bilt
A33: 46125 | B33: KLARNA*OVERSTOCK 041126 | C33: 134.75 | D33: Expense | E33: Shopping | F33: Checking
A34: 46125 | B34: SQ *MILK & PULL (RDG 041126 | C34: 6.8 | D34: Expense | E34: Dining | F34: Checking
A35: 46125 | B35: CITY FRESH MARKET PL 041026 | C35: 7.22 | D35: Expense | E35: Grocery | F35: Checking
A36: 46125 | B36: BURGER KING #1898 041026 | C36: 12.17 | D36: Expense | E36: Dining | F36: Checking
... A62: 46113 | B62: terra kaffe | C62: 69.14 | D62: Expense | E62: Dining | F62: Bilt
A63: 46070 | B63: Popeyes | C63: 12.5 | D63: Expense | E63: Dining | F63: Checking | G63: Roberto
A64: 46070 | B64: Koneko | C64: 19 | D64: Expense | E64: Misc | F64: Checking | G64: Roberto
A65: 46068 | B65: Amazon | C65: 9.16 | D65: Expense | E65: Shopping | F65: Apple Card | G65: Roberto
A66: 46068 | B66: Amazon | C66: 19.54 | D66: Expense | E66: Shopping | F66: Apple Card | G66: Roberto
A67: 46068 | B67: Amazon | C67: 9.45 | D67: Expense | E67: Shopping | F67: Apple Card | G67: Roberto
A68: 46066 | B68: Bodgega | C68: 5.2 | D68: Expense | E68: Misc | F68: Checking | G68: Roberto
A69: 46066 | B69: Groceries | C69: 70 | D69: Expense | E69: Grocery | F69: Checking
A70: 46065 | B70: City Fresh | C70: 12.29 | D70: Expense | E70: Grocery | F70: Checking | G70: Roberto
A71: 46064 | B71: City Fresh | C71: 34.18 | D71: Expense | E71: Grocery | F71: Checking | G71: Roberto
A72: 46063 | B72: Bodgega | C72: 5.72 | D72: Expense | E72: Misc | F72: Checking | G72: Roberto
A73: 46063 | B73: Tailor Home | C73: 15.46 | D73: Expense | E73: Misc | F73: Checking | G73: Roberto
...

Sheet Dashboard
A1: DASHBOARD
A2: Change Year/Month below. Log spends on the Log sheet — this page updates automatically.
A4: Year | B4: 2026 | C4: Month (1-12) | D4: 7 | F4: ← flip months here | H4: ACCOUNT BALANCES
A5: Period | B5: =DATE(B4,D4,1) | C5: to | D5: =EOMONTH(B5,0) | H5: (edit on Accounts)
H6: Account | I6: Balance / avail | J6: Owed
A7: INCOME (logged) | C7: SPENT (expenses) | E7: LOGGED NET | H7: =Accounts!A5 | I7: =Accounts!B5 | J7: =Accounts!C5
A8: =SUMIFS(Log!$C$5:$C$305,Log!$D$5:$D$305,"Income",Log!$A$5:$A$305,">="&$B$5,Log!$A$5:$A$305,"<="&$D$5) | C8: =SUMIFS(Log!$C$5:$C$305,Log!$D$5:$D$305,"Expense",Log!$A$5:$A$305,">="&$B$5,Log!$A$5:$A$305,"<="&$D$5) | E8: =A8-C8 | H8: =Accounts!A6 | I8: =Accounts!B6 | J8: =Accounts!C6
A9: From Log rows this month only | E9: PLANNED LEFT (main number) | H9: =Accounts!A7 | I9: =Accounts!B7 | J9: =Accounts!C7
A10: Expected monthly income (Income Plan) minus expenses logged this month. Use this as “can I still spend?” | E10: =('Income Plan'!B12)-C8 | H10: =Accounts!A8 | I10: =Accounts!B8 | J10: =Accounts!C8
H11: =Accounts!A9 | I11: =Accounts!B9 | J11: =Accounts!C9
A12: CATEGORY vs BUDGET | H12: =Accounts!A10 | I12: =Accounts!B10 | J12: =Accounts!C10
A13: Category | B13: Budget | C13: Spent | D13: Left | E13: % Used | F13: Status | H13: =Accounts!A11 | I13: =Accounts!B11 | J13: =Accounts!C11
A14: Rent | B14: =IFERROR(VLOOKUP(A14,Budget!$A$5:$B$30,2,FALSE),0) | C14: =SUMIFS(Log!$C$5:$C$305,Log!$E$5:$E$305,A14,Log!$D$5:$D$305,"Expense",Log!$A$5:$A$305,">="&$B$5,Log!$A$5:$A$305,"<="&$D$5) | D14: =B14-C14 | E14: =IF(B14=0,IF(C14>0,1,0),C14/B14) | F14: =IF(B14=0,"—",IF(C14>B14,"OVER",IF(C14/B14>=0.9,"CLOSE","OK"))) | H14: =Accounts!A12 | I14: =Accounts!B12 | J14: =Accounts!C12
A15: Utilities | B15: =IFERROR(VLOOKUP(A15,Budget!$A$5:$B$30,2,FALSE),0) | C15: =SUMIFS(Log!$C$5:$C$305,Log!$E$5:$E$305,A15,Log!$D$5:$D$305,"Expense",Log!$A$5:$A$305,">="&$B$5,Log!$A$5:$A$305,"<="&$D$5) | D15: =B15-C15 | E15: =IF(B15=0,IF(C15>0,1,0),C15/B15) | F15: =IF(B15=0,"—",IF(C15>B15,"OVER",IF(C15/B15>=0.9,"CLOSE","OK"))) | H15: =Accounts!A13 | I15: =Accounts!B13 | J15: =Accounts!C13
A16: Subscriptions | B16: =IFERROR(VLOOKUP(A16,Budget!$A$5:$B$30,2,FALSE),0) | C16: =SUMIFS(Log!$C$5:$C$305,Log!$E$5:$E$305,A16,Log!$D$5:$D$305,"Expense",Log!$A$5:$A$305,">="&$B$5,Log!$A$5:$A$305,"<="&$D$5) | D16: =B16-C16 | E16: =IF(B16=0,IF(C16>0,1,0),C16/B16) | F16: =IF(B16=0,"—",IF(C16>B16,"OVER",IF(C16/B16>=0.9,"CLOSE","OK")))
A17: Grocery | B17: =IFERROR(VLOOKUP(A17,Budget!$A$5:$B$30,2,FALSE),0) | C17: =SUMIFS(Log!$C$5:$C$305,Log!$E$5:$E$305,A17,Log!$D$5:$D$305,"Expense",Log!$A$5:$A$305,">="&$B$5,Log!$A$5:$A$305,"<="&$D$5) | D17: =B17-C17 | E17: =IF(B17=0,IF(C17>0,1,0),C17/B17) | F17: =IF(B17=0,"—",IF(C17>B17,"OVER",IF(C17/B17>=0.9,"CLOSE","OK"))) | H17: Total credit owed | I17: =Accounts!B14
A18: Dining | B18: =IFERROR(VLOOKUP(A18,Budget!$A$5:$B$30,2,FALSE),0) | C18: =SUMIFS(Log!$C$5:$C$305,Log!$E$5:$E$305,A18,Log!$D$5:$D$305,"Expense",Log!$A$5:$A$305,">="&$B$5,Log!$A$5:$A$305,"<="&$D$5) | D18: =B18-C18 | E18: =IF(B18=0,IF(C18>0,1,0),C18/B18) | F18: =IF(B18=0,"—",IF(C18>B18,"OVER",IF(C18/B18>=0.9,"CLOSE","OK")))
A19: Transit | B19: =IFERROR(VLOOKUP(A19,Budget!$A$5:$B$30,2,FALSE),0) | C19: =SUMIFS(Log!$C$5:$C$305,Log!$E$5:$E$305,A19,Log!$D$5:$D$305,"Expense",Log!$A$5:$A$305,">="&$B$5,Log!$A$5:$A$305,"<="&$D$5) | D19: =B19-C19 | E19: =IF(B19=0,IF(C19>0,1,0),C19/B19) | F19: =IF(B19=0,"—",IF(C19>B19,"OVER",IF(C19/B19>=0.9,"CLOSE","OK")))
A20: Shopping | B20: =IFERROR(VLOOKUP(A20,Budget!$A$5:$B$30,2,FALSE),0) | C20: =SUMIFS(Log!$C$5:$C$305,Log!$E$5:$E$305,A20,Log!$D$5:$D$305,"Expense",Log!$A$5:$A$305,">="&$B$5,Log!$A$5:$A$305,"<="&$D$5) | D20: =B20-C20 | E20: =IF(B20=0,IF(C20>0,1,0),C20/B20) | F20: =IF(B20=0,"—",IF(C20>B20,"OVER",IF(C20/B20>=0.9,"CLOSE","OK")))
A21: Personal | B21: =IFERROR(VLOOKUP(A21,Budget!$A$5:$B$30,2,FALSE),0) | C21: =SUMIFS(Log!$C$5:$C$305,Log!$E$5:$E$305,A21,Log!$D$5:$D$305,"Expense",Log!$A$5:$A$305,">="&$B$5,Log!$A$5:$A$305,"<="&$D$5) | D21: =B21-C21 | E21: =IF(B21=0,IF(C21>0,1,0),C21/B21) | F21: =IF(B21=0,"—",IF(C21>B21,"OVER",IF(C21/B21>=0.9,"CLOSE","OK")))
A22: Home | B22: =IFERROR(VLOOKUP(A22,Budget!$A$5:$B$30,2,FALSE),0) | C22: =SUMIFS(Log!$C$5:$C$305,Log!$E$5:$E$305,A22,Log!$D$5:$D$305,"Expense",Log!$A$5:$A$305,">="&$B$5,Log!$A$5:$A$305,"<="&$D$5) | D22: =B22-C22 | E22: =IF(B22=0,IF(C22>0,1,0),C22/B22) | F22: =IF(B22=0,"—",IF(C22>B22,"OVER",IF(C22/B22>=0.9,"CLOSE","OK")))
A23: Health | B23: =IFERROR(VLOOKUP(A23,Budget!$A$5:$B$30,2,FALSE),0) | C23: =SUMIFS(Log!$C$5:$C$305,Log!$E$5:$E$305,A23,Log!$D$5:$D$305,"Expense",Log!$A$5:$A$305,">="&$B$5,Log!$A$5:$A$305,"<="&$D$5) | D23: =B23-C23 | E23: =IF(B23=0,IF(C23>0,1,0),C23/B23) | F23: =IF(B23=0,"—",IF(C23>B23,"OVER",IF(C23/B23>=0.9,"CLOSE","OK")))
A24: Entertainment | B24: =IFERROR(VLOOKUP(A24,Budget!$A$5:$B$30,2,FALSE),0) | C24: =SUMIFS(Log!$C$5:$C$305,Log!$E$5:$E$305,A24,Log!$D$5:$D$305,"Expense",Log!$A$5:$A$305,">="&$B$5,Log!$A$5:$A$305,"<="&$D$5) | D24: =B24-C24 | E24: =IF(B24=0,IF(C24>0,1,0),C24/B24) | F24: =IF(B24=0,"—",IF(C24>B24,"OVER",IF(C24/B24>=0.9,"CLOSE","OK")))
A25: Savings | B25: =IFERROR(VLOOKUP(A25,Budget!$A$5:$B$30,2,FALSE),0) | C25: =SUMIFS(Log!$C$5:$C$305,Log!$E$5:$E$305,A25,Log!$D$5:$D$305,"Expense",Log!$A$5:$A$305,">="&$B$5,Log!$A$5:$A$305,"<="&$D$5) | D25: =B25-C25 | E25: =IF(B25=0,IF(C25>0,1,0),C25/B25) | F25: =IF(B25=0,"—",IF(C25>B25,"OVER",IF(C25/B25>=0.9,"CLOSE","OK")))
A26: Misc | B26: =IFERROR(VLOOKUP(A26,Budget!$A$5:$B$30,2,FALSE),0) | C26: =SUMIFS(Log!$C$5:$C$305,Log!$E$5:$E$305,A26,Log!$D$5:$D$305,"Expense",Log!$A$5:$A$305,">="&$B$5,Log!$A$5:$A$305,"<="&$D$5) | D26: =B26-C26 | E26: =IF(B26=0,IF(C26>0,1,0),C26/B26) | F26: =IF(B26=0,"—",IF(C26>B26,"OVER",IF(C26/B26>=0.9,"CLOSE","OK")))
A27: TOTAL | B27: =SUM(B14:B26) | C27: =SUM(C14:C26) | D27: =B27-C27
A29: SPEND BY ACCOUNT (this month)
A30: Account | B30: Spent
A31: Checking | B31: =SUMIFS(Log!$C$5:$C$305,Log!$F$5:$F$305,A31,Log!$D$5:$D$305,"Expense",Log!$A$5:$A$305,">="&$B$5,Log!$A$5:$A$305,"<="&$D$5)
A32: Bilt | B32: =SUMIFS(Log!$C$5:$C$305,Log!$F$5:$F$305,A32,Log!$D$5:$D$305,"Expense",Log!$A$5:$A$305,">="&$B$5,Log!$A$5:$A$305,"<="&$D$5)
A33: Apple Card | B33: =SUMIFS(Log!$C$5:$C$305,Log!$F$5:$F$305,A33,Log!$D$5:$D$305,"Expense",Log!$A$5:$A$305,">="&$B$5,Log!$A$5:$A$305,"<="&$D$5)
A34: USAA Credit Card | B34: =SUMIFS(Log!$C$5:$C$305,Log!$F$5:$F$305,A34,Log!$D$5:$D$305,"Expense",Log!$A$5:$A$305,">="&$B$5,Log!$A$5:$A$305,"<="&$D$5)
A35: PayPal | B35: =SUMIFS(Log!$C$5:$C$305,Log!$F$5:$F$305,A35,Log!$D$5:$D$305,"Expense",Log!$A$5:$A$305,">="&$B$5,Log!$A$5:$A$305,"<="&$D$5)
A36: Klarna | B36: =SUMIFS(Log!$C$5:$C$305,Log!$F$5:$F$305,A36,Log!$D$5:$D$305,"Expense",Log!$A$5:$A$305,">="&$B$5,Log!$A$5:$A$305,"<="&$D$5)
A37: Ally Savings | B37: =SUMIFS(Log!$C$5:$C$305,Log!$F$5:$F$305,A37,Log!$D$5:$D$305,"Expense",Log!$A$5:$A$305,">="&$B$5,Log!$A$5:$A$305,"<="&$D$5)
A38: Cash | B38: =SUMIFS(Log!$C$5:$C$305,Log!$F$5:$F$305,A38,Log!$D$5:$D$305,"Expense",Log!$A$5:$A$305,">="&$B$5,Log!$A$5:$A$305,"<="&$D$5)
A39: Other | B39: =SUMIFS(Log!$C$5:$C$305,Log!$F$5:$F$305,A39,Log!$D$5:$D$305,"Expense",Log!$A$5:$A$305,">="&$B$5,Log!$A$5:$A$305,"<="&$D$5)

Sheet Budget
A1: MONTHLY BUDGET TARGETS
A2: Edit the yellow cells. Dashboard compares this month’s Log against these targets.
A4: Category | B4: Monthly Budget | C4: Notes
A5: Rent | B5: 1120 | C5: Monthly rent
A6: Utilities | B6: 80 | C6: ConEd + National Grid typical
A7: Subscriptions | B7: 254 | C7: ~monthly recurrings
A8: Grocery | B8: 400 | C8: DoorDash + City Fresh
A9: Dining | B9: 200 | C9: Coffee, bodega, restaurants
A10: Transit | B10: 60 | C10: Monthly transit
A11: Shopping | B11: 150 | C11: Amazon / retail
A12: Personal | B12: 75 | C12: Personal care
A13: Home | B13: 50 | C13: Hardware / apartment
A14: Health | B14: 20 | C14: Beyond listed meds
A15: Entertainment | B15: 40 | C15: Outings
A16: Savings | B16: 200 | C16: To Ally
A17: Misc | B17: 100 | C17: Buffer
A18: TOTAL BUDGET | B18: =SUM(B5:B17)

Sheet Income Plan
A1: INCOME PLAN
A2: Expected money in for a normal month. Powers Dashboard “Planned left”.
A4: Source | B4: Amount | C4: Cadence | D4: Notes
A5: Paycheck 1 | B5: 1615 | C5: Biweekly | D5: Checking
A6: Paycheck 2 | B6: 1615 | C6: Biweekly | D6: Checking
A7: Alliance Stipend | B7: 75 | C7: Monthly | D7: Offsets internet
A8: Extra income | B8: 0 | C8: Variable | D8: Gigs, refunds
A10: Expected monthly income | B10: =SUM(B5:B8)
A12: Dashboard reference | B12: =B10
A14: When paid: Log row with Type=Income, Category=Income.

Sheet Recurring
A1: RECURRING BILLS & SUBSCRIPTIONS
A2: Checklist of what should hit. Still log each charge on Log so the month totals stay correct.
A4: Name | B4: Amount | C4: Frequency | D4: Category | E4: Account | F4: Active | G4: Monthly $ | H4: Notes
A5: Rent | B5: 1120 | C5: Monthly | D5: Rent | E5: Checking | F5: Y | G5: =IF(F5<>"Y",0,IF(C5="Annually",B5/12,IF(C5="Quarterly",B5/3,IF(C5="Weekly",B5*52/12,IF(C5="Biweekly",B5*26/12,B5)))))
A6: Electricity (ConEd) | B6: 52 | C6: Monthly | D6: Utilities | E6: Checking | F6: Y | G6: =IF(F6<>"Y",0,IF(C6="Annually",B6/12,IF(C6="Quarterly",B6/3,IF(C6="Weekly",B6*52/12,IF(C6="Biweekly",B6*26/12,B6))))) | H6: Varies
A7: Gas (National Grid) | B7: 26 | C7: Monthly | D7: Utilities | E7: Checking | F7: Y | G7: =IF(F7<>"Y",0,IF(C7="Annually",B7/12,IF(C7="Quarterly",B7/3,IF(C7="Weekly",B7*52/12,IF(C7="Biweekly",B7*26/12,B7)))))
A8: Transit | B8: 60 | C8: Monthly | D8: Transit | E8: Checking | F8: Y | G8: =IF(F8<>"Y",0,IF(C8="Annually",B8/12,IF(C8="Quarterly",B8/3,IF(C8="Weekly",B8*52/12,IF(C8="Biweekly",B8*26/12,B8)))))
A9: Savings transfer | B9: 200 | C9: Monthly | D9: Savings | E9: Ally Savings | F9: Y | G9: =IF(F9<>"Y",0,IF(C9="Annually",B9/12,IF(C9="Quarterly",B9/3,IF(C9="Weekly",B9*52/12,IF(C9="Biweekly",B9*26/12,B9))))) | H9: Pay yourself first
A10: Amazon Prime | B10: 16.32 | C10: Monthly | D10: Subscriptions | E10: Bilt | F10: Y | G10: =IF(F10<>"Y",0,IF(C10="Annually",B10/12,IF(C10="Quarterly",B10/3,IF(C10="Weekly",B10*52/12,IF(C10="Biweekly",B10*26/12,B10)))))
A11: Splice | B11: 12 | C11: Monthly | D11: Subscriptions | E11: Bilt | F11: Y | G11: =IF(F11<>"Y",0,IF(C11="Annually",B11/12,IF(C11="Quarterly",B11/3,IF(C11="Weekly",B11*52/12,IF(C11="Biweekly",B11*26/12,B11)))))
A12: iCloud | B12: 2.99 | C12: Monthly | D12: Subscriptions | E12: Apple Card | F12: Y | G12: =IF(F12<>"Y",0,IF(C12="Annually",B12/12,IF(C12="Quarterly",B12/3,IF(C12="Weekly",B12*52/12,IF(C12="Biweekly",B12*26/12,B12)))))
A13: Tidal | B13: 19 | C13: Monthly | D13: Subscriptions | E13: Bilt | F13: Y | G13: =IF(F13<>"Y",0,IF(C13="Annually",B13/12,IF(C13="Quarterly",B13/3,IF(C13="Weekly",B13*52/12,IF(C13="Biweekly",B13*26/12,B13))))) | H13: 17th of every month
A14: Internet | B14: 50 | C14: Monthly | D14: Subscriptions | E14: Bilt | F14: Y | G14: =IF(F14<>"Y",0,IF(C14="Annually",B14/12,IF(C14="Quarterly",B14/3,IF(C14="Weekly",B14*52/12,IF(C14="Biweekly",B14*26/12,B14))))) | H14: Alliance Stipend covers this
A15: Absolute Power | B15: 53.25 | C15: Monthly | D15: Subscriptions | E15: Bilt | F15: Y | G15: =IF(F15<>"Y",0,IF(C15="Annually",B15/12,IF(C15="Quarterly",B15/3,IF(C15="Weekly",B15*52/12,IF(C15="Biweekly",B15*26/12,B15))))) | H15: 15th of every month
A16: finasteride | B16: 20 | C16: Monthly | D16: Subscriptions | E16: Bilt | F16: Y | G16: =IF(F16<>"Y",0,IF(C16="Annually",B16/12,IF(C16="Quarterly",B16/3,IF(C16="Weekly",B16*52/12,IF(C16="Biweekly",B16*26/12,B16)))))
A17: Google Cloud | B17: 20 | C17: Monthly | D17: Subscriptions | E17: Checking | F17: Y | G17: =IF(F17<>"Y",0,IF(C17="Annually",B17/12,IF(C17="Quarterly",B17/3,IF(C17="Weekly",B17*52/12,IF(C17="Biweekly",B17*26/12,B17))))) | H17: Cap ~$20 (was over before)
A18: CursorAI | B18: 60 | C18: Monthly | D18: Subscriptions | E18: Bilt | F18: Y | G18: =IF(F18<>"Y",0,IF(C18="Annually",B18/12,IF(C18="Quarterly",B18/3,IF(C18="Weekly",B18*52/12,IF(C18="Biweekly",B18*26/12,B18)))))
A19: Soundiiz | B19: 24 | C19: Annually | D19: Subscriptions | E19: Bilt | F19: Y | G19: =IF(F19<>"Y",0,IF(C19="Annually",B19/12,IF(C19="Quarterly",B19/3,IF(C19="Weekly",B19*52/12,IF(C19="Biweekly",B19*26/12,B19)))))
A20: Healthy Vocal | B20: 40 | C20: Annually | D20: Subscriptions | E20: Bilt | F20: Y | G20: =IF(F20<>"Y",0,IF(C20="Annually",B20/12,IF(C20="Quarterly",B20/3,IF(C20="Weekly",B20*52/12,IF(C20="Biweekly",B20*26/12,B20)))))
A21: Apple Dev program | B21: 99 | C21: Annually | D21: Subscriptions | E21: Bilt | F21: Y | G21: =IF(F21<>"Y",0,IF(C21="Annually",B21/12,IF(C21="Quarterly",B21/3,IF(C21="Weekly",B21*52/12,IF(C21="Biweekly",B21*26/12,B21)))))
A23: Monthly equivalent total (active) | B23: =SUM(G5:G21)

Sheet Accounts
A1: ACCOUNTS & BALANCES
A2: Update when you check the bank. For credit cards, put amount OWED in column C.
A4: Account | B4: Balance / Available | C4: Owed (cards) | D4: Type | E4: Last updated | F4: Notes
A5: Checking | B5: 0 | C5: 0 | D5: Bank | F5: Primary spending
A6: Bilt | B6: 0 | C6: 328.5 | D6: Credit card | E6: 46162 | F6: Update from app
A7: Apple Card | B7: 0 | C7: 0 | D7: Credit card
A8: USAA Credit Card | B8: 0 | C8: 0 | D8: Credit card
A9: PayPal | B9: 0 | C9: 0 | D9: Wallet
A10: Klarna | B10: 0 | C10: 0 | D10: BNPL
A11: Ally Savings | B11: 8525.55 | C11: 0 | D11: Savings | E11: 46174 | F11: From investment snapshot
A12: Cash | B12: 0 | C12: 0 | D12: Cash
A13: Other | B13: 0 | C13: 0 | D13: Other
A14: Total credit owed | B14: =SUM(C5:C13)
A15: Total cash-like balances | B15: =SUM(B5:B13)

Sheet Investments
A1: INVESTMENTS
A2: Snapshots over time. Add a new date column when you re-check balances.
A4: Description | B4: Platform | C4: Ticker | D4: Purchase cost | E4: 2025-02-01 | F4: 2025-09-01 | G4: 2026-02-01 | H4: 2026-06-01 | I4: 2026-10-01
A5: AMPED 401k | B5: Fidelity | E5: 15163 | F5: 19445.56 | G5: 24894.63 | H5: 26311.35 | I5: 20582.94
A6: IRA | B6: Inspira | C6: VUG | D6: -3795 | E6: 5874.26 | F6: 6536.87 | G6: 6495 | H6: 7403 | I6: 6717.47
A7: Individual Investment | B7: Fidelity | C7: VOO/VUG | E7: 512.12 | F7: 556.36 | G7: 571.46 | H7: 632.36 | I7: 568.49
A8: Savings Account | B8: Ally | E8: 0 | F8: 0 | G8: 8260.62 | H8: 8525.55 | I8: 7375.81
A9: Total | E9: =SUM(E5:E8) | F9: =SUM(F5:F8) | G9: =SUM(G5:G8) | H9: =SUM(H5:H8) | I9: =SUM(I5:I8)
A10: % change vs prior | F10: =IF(E9=0,0,1-(E9/F9)) | G10: =IF(F9=0,0,1-(F9/G9)) | H10: =IF(G9=0,0,1-(G9/H9)) | I10: =IF(H9=0,0,1-(H9/I9))

Sheet Wishlist
A1: WISHLIST / HOME PROJECTS
A2: Separated from spending so money logging stays clean.
A4: Area | B4: Item | C4: Est. Price | D4: Status | E4: Notes
A5: Living room | B5: Orxva Oak Wood Media Console | C5: 1900 | D5: Now
A6: Living room | B6: GVAWood Console | C6: 1300 | D6: Now
A7: Living room | B7: Vacuum sealed bags | C7: 32 | D7: Now
A8: Bathroom | B8: Paint Bathroom | D8: Now
A9: Bathroom | B9: Do deep mold cleaning | D9: Now
A10: Bathroom | B10: Waste Bin | C10: 30 | D10: Now
A11: Bathroom | B11: Recaulk bathroom | D11: Now
A12: Bathroom | B12: Sunshower curtain (black) | D12: Now
A13: Kitchen | B13: Clean ceiling | D13: Now
A14: Kitchen | B14: Touch up black paint | D14: Now
A15: Kitchen | B15: Sheet metal for credenza | D15: Now
A16: Kitchen | B16: Dining chairs | D16: Now
A17: Kitchen | B17: put shelfs in basemrnt | D17: Now
A18: Kitchen | B18: Ikea Besta Cabinet | D18: Now
A19: Kitchen | B19: Patch holes | D19: Now
A20: Kitchen | B20: Paint over holes | D20: Now
A21: Creative/Studio | B21: Mirror | D21: Now
A22: Creative/Studio | B22: Ledge | D22: Now
A23: Personal | B23: Write todo list for deep cleaining | D23: Now
A24: Living room | B24: Ikea Besta frames | C24: 75 | D24: Later
A25: Living room | B25: Safavieh Grey Washable Rug (4x6) (Safavieh) | C25: 83 | D25: Later
A26: Living room | B26: Mirror | D26: Later
A27: Living room | B27: Make wooden enclosure for coat closet | D27: Later
A28: Kitchen | B28: Recaulk kitchen | D28: Later
A29: Kitchen | B29: Plywood enclosure of washer | D29: Later
A30: Kitchen | B30: Remove paint from cabinets | D30: Later
A31: Kitchen | B31: Sheet metal for credenza | D31: Later
A32: Kitchen | B32: Dining chairs | D32: Later
A33: Kitchen | B33: put shelfs in basemrnt | D33: Later
A34: Kitchen | B34: Ikea Besta Cabinet | D34: Later
A35: Creative/Studio | B35: Vinyl Lab Stool | C35: 190 | D35: Later
A36: Creative/Studio | B36: Stainless Steel Sheets (2x4) | C36: 75 | D36: Later
A37: Creative/Studio | B37: 2x4 Baltic Birch top | C37: 150 | D37: Later
A38: Creative/Studio | B38: XKey Midi Ctrl | C38: 300 | D38: Later
A39: Living room | B39: get a digital console piano | C39: 1000 | D39: Never
A40: Creative/Studio | B40: Ultimate keyboard support stand | C40: 229 | D40: Never
A41: Creative/Studio | B41: RX1200 sample machine plugin | C41: 30 | D41: Never
...

Sheet Setup
A1: Categories | B1: Accounts | C1: People | D1: Types | E1: Frequencies
A2: Income | B2: Checking | C2: Roberto | D2: Expense | E2: Weekly
A3: Rent | B3: Bilt | C3: Cliff | D3: Income | E3: Biweekly
A4: Utilities | B4: Apple Card | C4: Cliff/Roberto | D4: Transfer | E4: Monthly
A5: Subscriptions | B5: USAA Credit Card | C5: Shared | E5: Quarterly
A6: Grocery | B6: PayPal | C6: Other | E6: Annually
A7: Dining | B7: Klarna | E7: One-time
A8: Transit | B8: Ally Savings
A9: Shopping | B9: Cash
A10: Personal | B10: Other
A11: Home
A12: Health
A13: Entertainment
A14: Savings
A15: Transfer
A16: Misc
