Workbook

Sheet This Month
A1: MONEY
A2: This month
A3: Bills (rent/subs) auto-count. You only log day-to-day on Log.
A5: YEAR | B5: MONTH | C5: PERIOD | F5: BALANCES
A6: 2026 | B6: 7 | C6: =DATE(A6,B6,1) | D6: =EOMONTH(C6,0) | F6: ACCOUNT | G6: HAVE | H6: OWE
F7: =Balances!A5 | G7: =Balances!B5 | H7: =Balances!C5
A8: REMAINING | F8: =Balances!A6 | G8: =Balances!B6 | H8: =Balances!C6
A9: ='Plan'!B20-'Plan'!B21-B12 | F9: =Balances!A7 | G9: =Balances!B7 | H9: =Balances!C7
A10: Income − automatic bills − day-to-day logged this month | F10: =Balances!A8 | G10: =Balances!B8 | H10: =Balances!C8
A11: IN | B11: DAY-TO-DAY | C11: BILLS (AUTO) | D11: NET LOGGED | F11: =Balances!A9 | G11: =Balances!B9 | H11: =Balances!C9
A12: =SUMIFS(Log!$C$5:$C$311,Log!$D$5:$D$311,"Income",Log!$A$5:$A$311,">="&$C$6,Log!$A$5:$A$311,"<="&$D$6) | B12: =SUMIFS(Log!$C$5:$C$311,Log!$D$5:$D$311,"Expense",Log!$A$5:$A$311,">="&$C$6,Log!$A$5:$A$311,"<="&$D$6) | C12: ='Plan'!B21 | D12: =A12-B12 | F12: =Balances!A10 | G12: =Balances!B10 | H12: =Balances!C10
F13: =Balances!A11 | G13: =Balances!B11 | H13: =Balances!C11
A14: BY CATEGORY | F14: =Balances!A12 | G14: =Balances!B12 | H14: =Balances!C12
A15: CATEGORY | B15: PLAN | C15: SPENT | D15: LEFT | F15: =Balances!A13 | G15: =Balances!B13 | H15: =Balances!C13
A16: Rent | B16: =IFERROR(VLOOKUP(A16,Plan!$A$6:$B$18,2,FALSE),0) | C16: =SUMIFS(Log!$C$5:$C$311,Log!$E$5:$E$311,A16,Log!$D$5:$D$311,"Expense",Log!$A$5:$A$311,">="&$C$6,Log!$A$5:$A$311,"<="&$D$6)+IFERROR(VLOOKUP(A16,Plan!$H$6:$I$20,2,FALSE),0) | D16: =B16-C16
A17: Utilities | B17: =IFERROR(VLOOKUP(A17,Plan!$A$6:$B$18,2,FALSE),0) | C17: =SUMIFS(Log!$C$5:$C$311,Log!$E$5:$E$311,A17,Log!$D$5:$D$311,"Expense",Log!$A$5:$A$311,">="&$C$6,Log!$A$5:$A$311,"<="&$D$6)+IFERROR(VLOOKUP(A17,Plan!$H$6:$I$20,2,FALSE),0) | D17: =B17-C17 | F17: OWED TOTAL | G17: =Balances!B15
A18: Subscriptions | B18: =IFERROR(VLOOKUP(A18,Plan!$A$6:$B$18,2,FALSE),0) | C18: =SUMIFS(Log!$C$5:$C$311,Log!$E$5:$E$311,A18,Log!$D$5:$D$311,"Expense",Log!$A$5:$A$311,">="&$C$6,Log!$A$5:$A$311,"<="&$D$6)+IFERROR(VLOOKUP(A18,Plan!$H$6:$I$20,2,FALSE),0) | D18: =B18-C18
A19: Grocery | B19: =IFERROR(VLOOKUP(A19,Plan!$A$6:$B$18,2,FALSE),0) | C19: =SUMIFS(Log!$C$5:$C$311,Log!$E$5:$E$311,A19,Log!$D$5:$D$311,"Expense",Log!$A$5:$A$311,">="&$C$6,Log!$A$5:$A$311,"<="&$D$6)+IFERROR(VLOOKUP(A19,Plan!$H$6:$I$20,2,FALSE),0) | D19: =B19-C19
A20: Dining | B20: =IFERROR(VLOOKUP(A20,Plan!$A$6:$B$18,2,FALSE),0) | C20: =SUMIFS(Log!$C$5:$C$311,Log!$E$5:$E$311,A20,Log!$D$5:$D$311,"Expense",Log!$A$5:$A$311,">="&$C$6,Log!$A$5:$A$311,"<="&$D$6)+IFERROR(VLOOKUP(A20,Plan!$H$6:$I$20,2,FALSE),0) | D20: =B20-C20
A21: Transit | B21: =IFERROR(VLOOKUP(A21,Plan!$A$6:$B$18,2,FALSE),0) | C21: =SUMIFS(Log!$C$5:$C$311,Log!$E$5:$E$311,A21,Log!$D$5:$D$311,"Expense",Log!$A$5:$A$311,">="&$C$6,Log!$A$5:$A$311,"<="&$D$6)+IFERROR(VLOOKUP(A21,Plan!$H$6:$I$20,2,FALSE),0) | D21: =B21-C21
A22: Shopping | B22: =IFERROR(VLOOKUP(A22,Plan!$A$6:$B$18,2,FALSE),0) | C22: =SUMIFS(Log!$C$5:$C$311,Log!$E$5:$E$311,A22,Log!$D$5:$D$311,"Expense",Log!$A$5:$A$311,">="&$C$6,Log!$A$5:$A$311,"<="&$D$6)+IFERROR(VLOOKUP(A22,Plan!$H$6:$I$20,2,FALSE),0) | D22: =B22-C22
A23: Personal | B23: =IFERROR(VLOOKUP(A23,Plan!$A$6:$B$18,2,FALSE),0) | C23: =SUMIFS(Log!$C$5:$C$311,Log!$E$5:$E$311,A23,Log!$D$5:$D$311,"Expense",Log!$A$5:$A$311,">="&$C$6,Log!$A$5:$A$311,"<="&$D$6)+IFERROR(VLOOKUP(A23,Plan!$H$6:$I$20,2,FALSE),0) | D23: =B23-C23
A24: Home | B24: =IFERROR(VLOOKUP(A24,Plan!$A$6:$B$18,2,FALSE),0) | C24: =SUMIFS(Log!$C$5:$C$311,Log!$E$5:$E$311,A24,Log!$D$5:$D$311,"Expense",Log!$A$5:$A$311,">="&$C$6,Log!$A$5:$A$311,"<="&$D$6)+IFERROR(VLOOKUP(A24,Plan!$H$6:$I$20,2,FALSE),0) | D24: =B24-C24
A25: Health | B25: =IFERROR(VLOOKUP(A25,Plan!$A$6:$B$18,2,FALSE),0) | C25: =SUMIFS(Log!$C$5:$C$311,Log!$E$5:$E$311,A25,Log!$D$5:$D$311,"Expense",Log!$A$5:$A$311,">="&$C$6,Log!$A$5:$A$311,"<="&$D$6)+IFERROR(VLOOKUP(A25,Plan!$H$6:$I$20,2,FALSE),0) | D25: =B25-C25
A26: Entertainment | B26: =IFERROR(VLOOKUP(A26,Plan!$A$6:$B$18,2,FALSE),0) | C26: =SUMIFS(Log!$C$5:$C$311,Log!$E$5:$E$311,A26,Log!$D$5:$D$311,"Expense",Log!$A$5:$A$311,">="&$C$6,Log!$A$5:$A$311,"<="&$D$6)+IFERROR(VLOOKUP(A26,Plan!$H$6:$I$20,2,FALSE),0) | D26: =B26-C26
A27: Savings | B27: =IFERROR(VLOOKUP(A27,Plan!$A$6:$B$18,2,FALSE),0) | C27: =SUMIFS(Log!$C$5:$C$311,Log!$E$5:$E$311,A27,Log!$D$5:$D$311,"Expense",Log!$A$5:$A$311,">="&$C$6,Log!$A$5:$A$311,"<="&$D$6)+IFERROR(VLOOKUP(A27,Plan!$H$6:$I$20,2,FALSE),0) | D27: =B27-C27
A28: Misc | B28: =IFERROR(VLOOKUP(A28,Plan!$A$6:$B$18,2,FALSE),0) | C28: =SUMIFS(Log!$C$5:$C$311,Log!$E$5:$E$311,A28,Log!$D$5:$D$311,"Expense",Log!$A$5:$A$311,">="&$C$6,Log!$A$5:$A$311,"<="&$D$6)+IFERROR(VLOOKUP(A28,Plan!$H$6:$I$20,2,FALSE),0) | D28: =B28-C28
A29: TOTAL | B29: =SUM(B16:B28) | C29: =SUM(C16:C28) | D29: =B29-C29
A35: Flip month above · Log only day-to-day · Rent & subs auto-count from Plan

Sheet Log
A1: MONEY
A2: Log
A3: Day-to-day only (coffee, bodega, grocery, shopping). Rent & subscriptions auto-count from Plan — do not log those here.
A4: DATE | B4: WHAT | C4: AMOUNT | D4: TYPE | E4: CATEGORY | F4: ACCOUNT | G4: WHO | H4: NOTE
D5: Expense | F5: Checking | G5: Roberto
D6: Expense | F6: Checking | G6: Roberto
D7: Expense | F7: Checking | G7: Roberto
D8: Expense | F8: Checking | G8: Roberto
D9: Expense | F9: Checking | G9: Roberto
D10: Expense | F10: Checking | G10: Roberto
D11: Expense | F11: Checking | G11: Roberto
D12: Expense | F12: Checking | G12: Roberto
D13: Expense | F13: Checking | G13: Roberto
D14: Expense | F14: Checking | G14: Roberto
D15: Expense | F15: Checking | G15: Roberto
D16: Expense | F16: Checking | G16: Roberto
... D18: Expense | F18: Checking | G18: Roberto
A19: HISTORY
A20: 46163 | B20: Cat food | C20: 43.4 | D20: Expense | E20: Grocery | F20: Bilt
A21: 46163 | B21: Amazon: Protein Bars | C21: 14.99 | D21: Expense | E21: Shopping | F21: Bilt
A22: 46163 | B22: Grocery: City Fresh | C22: 39.19 | D22: Expense | E22: Grocery | F22: Bilt
A23: 46163 | B23: Amazon: Toothpast, Chlorophyll, Oil sprayer | C23: 51.01 | D23: Expense | E23: Shopping | F23: Bilt
A24: 46163 | B24: Grocery: Green Valley | C24: 21.46 | D24: Expense | E24: Grocery | F24: Bilt
A25: 46163 | B25: Rose Glycerin Spray | C25: 11.94 | D25: Expense | E25: Shopping | F25: Bilt
A26: 46163 | B26: Grocery: DoorDash | C26: 86 | D26: Expense | E26: Grocery | F26: Bilt
A27: 46163 | B27: Klarna | C27: 134.75 | D27: Expense | E27: Shopping | F27: Bilt
A28: 46125 | B28: KLARNA*OVERSTOCK 041126 | C28: 134.75 | D28: Expense | E28: Shopping | F28: Checking
A29: 46125 | B29: SQ *MILK & PULL (RDG 041126 | C29: 6.8 | D29: Expense | E29: Dining | F29: Checking
A30: 46125 | B30: CITY FRESH MARKET PL 041026 | C30: 7.22 | D30: Expense | E30: Grocery | F30: Checking
A31: 46125 | B31: BURGER KING #1898 041026 | C31: 12.17 | D31: Expense | E31: Dining | F31: Checking
... A57: 46113 | B57: terra kaffe | C57: 69.14 | D57: Expense | E57: Dining | F57: Bilt
A58: 46070 | B58: Popeyes | C58: 12.5 | D58: Expense | E58: Dining | F58: Checking | G58: Roberto
A59: 46070 | B59: Koneko | C59: 19 | D59: Expense | E59: Misc | F59: Checking | G59: Roberto
A60: 46068 | B60: Amazon | C60: 9.16 | D60: Expense | E60: Shopping | F60: Apple Card | G60: Roberto
A61: 46068 | B61: Amazon | C61: 19.54 | D61: Expense | E61: Shopping | F61: Apple Card | G61: Roberto
A62: 46068 | B62: Amazon | C62: 9.45 | D62: Expense | E62: Shopping | F62: Apple Card | G62: Roberto
A63: 46066 | B63: Bodgega | C63: 5.2 | D63: Expense | E63: Misc | F63: Checking | G63: Roberto
A64: 46066 | B64: Groceries | C64: 70 | D64: Expense | E64: Grocery | F64: Checking
A65: 46065 | B65: City Fresh | C65: 12.29 | D65: Expense | E65: Grocery | F65: Checking | G65: Roberto
A66: 46064 | B66: City Fresh | C66: 34.18 | D66: Expense | E66: Grocery | F66: Checking | G66: Roberto
...

Sheet Plan
A1: MONEY
A2: Plan
A3: Set once. Bills marked ON auto-subtract on This Month.
A4: SPEND TARGETS | D4: INCOME | H4: BILLS BY CATEGORY
A5: CATEGORY | B5: MONTHLY | D5: SOURCE | E5: AMOUNT | H5: CATEGORY | I5: MONTHLY
A6: Rent | B6: 1120 | D6: Paycheck 1 | E6: 1615 | H6: Rent | I6: =SUMIF($G$24:$G$40,H6,$F$24:$F$40)
A7: Utilities | B7: 80 | D7: Paycheck 2 | E7: 1615 | H7: Utilities | I7: =SUMIF($G$24:$G$40,H7,$F$24:$F$40)
A8: Subscriptions | B8: 254 | D8: Alliance Stipend | E8: 75 | H8: Subscriptions | I8: =SUMIF($G$24:$G$40,H8,$F$24:$F$40)
A9: Grocery | B9: 400 | D9: Extra income | E9: 0 | H9: Grocery | I9: =SUMIF($G$24:$G$40,H9,$F$24:$F$40)
A10: Dining | B10: 200 | H10: Dining | I10: =SUMIF($G$24:$G$40,H10,$F$24:$F$40)
A11: Transit | B11: 60 | D11: EXPECTED / MONTH | E11: =SUM(E6:E9) | H11: Transit | I11: =SUMIF($G$24:$G$40,H11,$F$24:$F$40)
A12: Shopping | B12: 150 | H12: Shopping | I12: =SUMIF($G$24:$G$40,H12,$F$24:$F$40)
A13: Personal | B13: 75 | H13: Personal | I13: =SUMIF($G$24:$G$40,H13,$F$24:$F$40)
A14: Home | B14: 50 | H14: Home | I14: =SUMIF($G$24:$G$40,H14,$F$24:$F$40)
A15: Health | B15: 20 | H15: Health | I15: =SUMIF($G$24:$G$40,H15,$F$24:$F$40)
A16: Entertainment | B16: 40 | H16: Entertainment | I16: =SUMIF($G$24:$G$40,H16,$F$24:$F$40)
A17: Savings | B17: 200 | H17: Savings | I17: =SUMIF($G$24:$G$40,H17,$F$24:$F$40)
A18: Misc | B18: 100 | H18: Misc | I18: =SUMIF($G$24:$G$40,H18,$F$24:$F$40)
A19: TOTAL | B19: =SUM(B6:B18)
A20: EXPECTED INCOME REF | B20: =E11
A21: BILLS AUTO-COUNT (monthly) | B21: =SUM(F24:F40)
A22: RECURRING
A23: NAME | B23: AMOUNT | C23: EVERY | D23: ACCOUNT | E23: ON | F23: MONTHLY | G23: CATEGORY
A24: Rent | B24: 1120 | C24: Monthly | D24: Checking | E24: Y | F24: =IF(E24<>"Y",0,IF(C24="Annually",B24/12,IF(C24="Quarterly",B24/3,IF(C24="Weekly",B24*52/12,IF(C24="Biweekly",B24*26/12,B24))))) | G24: Rent
A25: Electricity (ConEd) | B25: 52 | C25: Monthly | D25: Checking | E25: Y | F25: =IF(E25<>"Y",0,IF(C25="Annually",B25/12,IF(C25="Quarterly",B25/3,IF(C25="Weekly",B25*52/12,IF(C25="Biweekly",B25*26/12,B25))))) | G25: Utilities
A26: Gas (National Grid) | B26: 26 | C26: Monthly | D26: Checking | E26: Y | F26: =IF(E26<>"Y",0,IF(C26="Annually",B26/12,IF(C26="Quarterly",B26/3,IF(C26="Weekly",B26*52/12,IF(C26="Biweekly",B26*26/12,B26))))) | G26: Utilities
A27: Transit | B27: 60 | C27: Monthly | D27: Checking | E27: Y | F27: =IF(E27<>"Y",0,IF(C27="Annually",B27/12,IF(C27="Quarterly",B27/3,IF(C27="Weekly",B27*52/12,IF(C27="Biweekly",B27*26/12,B27))))) | G27: Transit
A28: Savings transfer | B28: 200 | C28: Monthly | D28: Ally Savings | E28: Y | F28: =IF(E28<>"Y",0,IF(C28="Annually",B28/12,IF(C28="Quarterly",B28/3,IF(C28="Weekly",B28*52/12,IF(C28="Biweekly",B28*26/12,B28))))) | G28: Savings
A29: Amazon Prime | B29: 16.32 | C29: Monthly | D29: Bilt | E29: Y | F29: =IF(E29<>"Y",0,IF(C29="Annually",B29/12,IF(C29="Quarterly",B29/3,IF(C29="Weekly",B29*52/12,IF(C29="Biweekly",B29*26/12,B29))))) | G29: Subscriptions
A30: Splice | B30: 12 | C30: Monthly | D30: Bilt | E30: Y | F30: =IF(E30<>"Y",0,IF(C30="Annually",B30/12,IF(C30="Quarterly",B30/3,IF(C30="Weekly",B30*52/12,IF(C30="Biweekly",B30*26/12,B30))))) | G30: Subscriptions
A31: iCloud | B31: 2.99 | C31: Monthly | D31: Apple Card | E31: Y | F31: =IF(E31<>"Y",0,IF(C31="Annually",B31/12,IF(C31="Quarterly",B31/3,IF(C31="Weekly",B31*52/12,IF(C31="Biweekly",B31*26/12,B31))))) | G31: Subscriptions
A32: Tidal | B32: 19 | C32: Monthly | D32: Bilt | E32: Y | F32: =IF(E32<>"Y",0,IF(C32="Annually",B32/12,IF(C32="Quarterly",B32/3,IF(C32="Weekly",B32*52/12,IF(C32="Biweekly",B32*26/12,B32))))) | G32: Subscriptions
A33: Internet | B33: 50 | C33: Monthly | D33: Bilt | E33: Y | F33: =IF(E33<>"Y",0,IF(C33="Annually",B33/12,IF(C33="Quarterly",B33/3,IF(C33="Weekly",B33*52/12,IF(C33="Biweekly",B33*26/12,B33))))) | G33: Subscriptions
A34: Absolute Power | B34: 53.25 | C34: Monthly | D34: Bilt | E34: Y | F34: =IF(E34<>"Y",0,IF(C34="Annually",B34/12,IF(C34="Quarterly",B34/3,IF(C34="Weekly",B34*52/12,IF(C34="Biweekly",B34*26/12,B34))))) | G34: Subscriptions
A35: finasteride | B35: 20 | C35: Monthly | D35: Bilt | E35: Y | F35: =IF(E35<>"Y",0,IF(C35="Annually",B35/12,IF(C35="Quarterly",B35/3,IF(C35="Weekly",B35*52/12,IF(C35="Biweekly",B35*26/12,B35))))) | G35: Subscriptions
... A40: Apple Dev program | B40: 99 | C40: Annually | D40: Bilt | E40: Y | F40: =IF(E40<>"Y",0,IF(C40="Annually",B40/12,IF(C40="Quarterly",B40/3,IF(C40="Weekly",B40*52/12,IF(C40="Biweekly",B40*26/12,B40))))) | G40: Subscriptions
A42: ON = auto-subtracted. Do not log these on Log — only day-to-day spends.

Sheet Balances
A1: MONEY
A2: Balances
A3: Update when you check the bank. Cards: amount owed in OWE.
A4: ACCOUNT | B4: HAVE | C4: OWE
A5: Checking | B5: 0 | C5: 0
A6: Bilt | B6: 0 | C6: 328.5
A7: Apple Card | B7: 0 | C7: 0
A8: USAA Credit Card | B8: 0 | C8: 0
A9: PayPal | B9: 0 | C9: 0
A10: Klarna | B10: 0 | C10: 0
A11: Ally Savings | B11: 8525.55 | C11: 0
A12: Cash | B12: 0 | C12: 0
A13: Other | B13: 0 | C13: 0
A15: OWED TOTAL | B15: =SUM(C5:C13)
A17: CASH-LIKE | B17: =SUM(B5:B13)

Sheet Lists
A1: Income | B1: Checking | C1: Roberto | D1: Expense | E1: Weekly
A2: Rent | B2: Bilt | C2: Cliff | D2: Income | E2: Biweekly
A3: Utilities | B3: Apple Card | C3: Cliff/Roberto | D3: Transfer | E3: Monthly
A4: Subscriptions | B4: USAA Credit Card | C4: Shared | E4: Quarterly
A5: Grocery | B5: PayPal | C5: Other | E5: Annually
A6: Dining | B6: Klarna
A7: Transit | B7: Ally Savings
A8: Shopping | B8: Cash
A9: Personal | B9: Other
A10: Home
A11: Health
A12: Entertainment
A13: Savings
A14: Transfer
A15: Misc
